<?xml version="1.0" ?>
<robot name="car">
	<link name="base"/>
	<link name="link_0">
		<visual name="out-frame">
			<origin xyz="0 0 0"/>
			<geometry>
				<mesh filename="texture_dae/car-board.dae" scale="0.3505217243431099 0.3505217243431099 0.3505217243431099"/>
			</geometry>
		</visual>
		<collision>
			<origin xyz="0 0 0"/>
			<geometry>
				<mesh filename="texture_dae/car-board.dae" scale="0.3505217243431099 0.3505217243431099 0.3505217243431099"/>
			</geometry>
		</collision>
	</link>
	<joint name="joint_0" type="fixed">
		<origin rpy="1.570796326794897 0 -1.570796326794897" xyz="0 0 0"/>
		<child link="link_0"/>
		<parent link="base"/>
	</joint>
	<link name="link_1">
		<visual name="surf-board">
			<origin xyz="1.0111848321342034 -0.4573272800359176 0"/>
			<geometry>
				<mesh filename="texture_dae/car-door.dae" scale="0.3505217243431099 0.3505217243431099 0.3505217243431099"/>
			</geometry>
		</visual>
		<collision>
			<origin xyz="1.0111848321342034 -0.4573272800359176 0"/>
			<geometry>
				<mesh filename="texture_dae/car-door.dae" scale="0.3505217243431099 0.3505217243431099 0.3505217243431099"/>
			</geometry>
		</collision>
	</link>
	<joint name="joint_1" type="revolute">
		<origin xyz="-1.0111848321342034 0.4573272800359176 0"/>
		<axis xyz="0 -1 0"/>
		<child link="link_1"/>
		<parent link="link_0"/>
		<limit lower="0" upper="1.5079644737231006"/>
	</joint>
	<link name="link_2">
		<visual name="handle-lock">
			<origin xyz="0 0 0"/>
			<geometry>
				<mesh filename="texture_dae/9968001-lock.dae" scale="1.0622982433678803 1.0622982433678803 1.0622982433678803"/>
			</geometry>
		</visual>
		<collision>
			<origin xyz="0 0 0"/>
			<geometry>
				<mesh filename="texture_dae/9968001-lock.dae" scale="1.0622982433678803 1.0622982433678803 1.0622982433678803"/>
			</geometry>
		</collision>
	</link>
	<joint name="joint_2" type="fixed">
		<origin xyz="1.0011848321342034 -0.4573272800359176 0.005"/>
		<child link="link_2"/>
		<parent link="link_1"/>
	</joint>
	<link name="link_3">
		<visual name="handle">
			<origin xyz="0 0 0"/>
			<geometry>
				<mesh filename="texture_dae/9968001-handle.dae" scale="1.0622982433678803 1.0622982433678803 1.0622982433678803"/>
			</geometry>
		</visual>
		<collision>
			<origin xyz="0 0 0"/>
			<geometry>
				<mesh filename="texture_dae/9968001-handle.dae" scale="1.0622982433678803 1.0622982433678803 1.0622982433678803"/>
			</geometry>
		</collision>
	</link>
	<joint name="joint_3" type="revolute">
		<origin xyz="0 0 0"/>
		<child link="link_3"/>
		<parent link="link_2"/>
		<axis xyz="0 -1 0"/>
		<limit lower="0" upper="0.17453"/>
	</joint>
</robot>
