<mujoco model="right-pull-door">
  <compiler angle="radian" meshdir="texture_stl/"/>

  <visual>
    <headlight diffuse="0.6 0.6 0.6" ambient="0.3 0.3 0.3" specular="0 0 0"/>
    <rgba haze="0.15 0.25 0.35 1"/>
    <global azimuth="-20" elevation="-20" ellipsoidinertia="true"/>
  </visual>

  <asset>
    <texture type="skybox" builtin="gradient" rgb1="0.3 0.5 0.7" rgb2="0 0 0" width="512" height="3072"/>
    <texture type="2d" name="groundplane" builtin="checker" mark="edge" rgb1="0.2 0.3 0.4" rgb2="0.1 0.2 0.3"
      markrgb="0.8 0.8 0.8" width="300" height="300"/>
    <texture name="wood" type="cube" file="texture_stl/texture_0.png"/>
    <texture name="knob" type="2d" file="texture_stl/texture_3.png"/>
    <material name="wood_material" texture="wood"/>
    <material name="knob_material" texture="knob"/>
    <material name="groundplane" texture="groundplane" texuniform="true" texrepeat="5 5" reflectance="0.2"/>

    <mesh name="frame" file="frame.stl" scale="0.8 0.8 0.8"/>
    <mesh name="board" file="board.stl" scale="0.8 0.8 0.8"/>
    <mesh name="9962004" file="9962004.stl" scale="1.45964 1.45964 1.45964"/>
  </asset>

  <worldbody>
    <light pos="0 0 1.5" dir="0 0 -1" directional="true"/>
    <geom name="floor" size="0 0 0.05" type="plane" material="groundplane"/>
    <body name="cabinet" euler="0 1.57 0" pos="0 0 1">
    <joint type="free"/>
    <geom name="out-frame" pos="0 0 0" quat="0.5 0.5 -0.5 -0.5" type="mesh" contype="0" conaffinity="0" group="1" density="0" mesh="frame" material="wood_material"/>
    <geom pos="0 0 0" quat="0.5 0.5 -0.5 -0.5" type="mesh" mesh="frame" material="wood_material"/>
        <!-- <body name="link_1" pos="0 0.562529 0.334649" quat="0.5 0.5 -0.5 -0.5"> -->
        <body name="link_1" pos="0 0.562529 0" quat="0.5 0.5 -0.5 -0.5">
        <joint name="joint_1" pos="0 0 0" axis="0 0 -1" range="0 1.50796"/>
        <geom name="surf-board" pos="0.562529 0 0" quat="1 0 0 0" type="mesh" contype="0" conaffinity="0" group="1" density="0" mesh="board" material="wood_material"/>
        <geom pos="0.562529 -0.334649 0" quat="1 0 0 0" type="mesh" mesh="board" material="wood_material"/>
            <body name="link_2" pos="0.562529 -0.334649 0.0133813">
            <joint name="joint_2" pos="0 0 0" axis="0 1 0" range="0 1.50796"/>
            <geom name="handle" type="mesh" contype="0" conaffinity="0" group="1" density="0" mesh="9962004" material="knob_material"/>
            <geom type="mesh" mesh="9962004" material="knob_material"/>
            </body>
        </body>
    </body>
  </worldbody>
</mujoco>
