<mujoco model="fridge">
  <compiler angle="radian" meshdir="texture_stl/"/>

  <visual>
    <headlight diffuse="0.6 0.6 0.6" ambient="0.3 0.3 0.3" specular="0 0 0"/>
    <rgba haze="0.15 0.25 0.35 1"/>
    <global azimuth="-20" elevation="-20" ellipsoidinertia="true"/>
  </visual>

  <asset>
    <texture type="skybox" builtin="gradient" rgb1="0.3 0.5 0.7" rgb2="0 0 0" width="512" height="3072"/>
    <texture type="2d" name="groundplane" builtin="checker" mark="edge" rgb1="0.2 0.3 0.4" rgb2="0.1 0.2 0.3"
      markrgb="0.8 0.8 0.8" width="300" height="300"/>
    <texture name="door_texture" type="cube" file="texture_stl/texture_0.png"/>
    <texture name="handle_texture" type="2d" file="texture_stl/texture_0.png"/>
    <material name="door_material" texture="door_texture"/>
    <material name="handle_material" texture="handle_texture"/>
    <material name="groundplane" texture="groundplane" texuniform="true" texrepeat="5 5" reflectance="0.2"/>

    <mesh name="frame" file="frame.stl" scale="0.8632881649119379 0.8632881649119379 0.8632881649119379"/>
    <mesh name="board" file="board.stl" scale="0.8632881649119379 0.8632881649119379 0.86328816491193794"/>
    <mesh name="9962026" file="9962026.stl" scale="0.7375794533982215 0.7375794533982215 0.7375794533982215"/>
  </asset>

  <worldbody>
    <light pos="0 0 1.5" dir="0 0 -1" directional="true"/>
    <geom name="floor" size="0 0 0.05" type="plane" material="groundplane"/>
    <body name="door" euler="0 1.57 0" pos="0 0 0.95">
<!--      <joint type="free"/>-->
      <geom name="frame" pos="0 0 0" quat="0.5 0.5 -0.5 -0.5" type="mesh" mesh="frame" material="door_material" conaffinity="0" contype="0"/>
      <body name="link_1" pos="0 0.4815588565752399 0" quat="0.5 0.5 -0.5 -0.5">
        <inertial pos="0 0 0" mass="10.0" diaginertia="5.0 5.0 5.0"/>
        <joint name="joint_1" pos="0 0 0" axis="0 0 -1" range="0 1.50796"/>
        <geom name="board" pos="0.4815588565752399 0 0" quat="1 0 0 0" type="mesh" mesh="board" material="door_material"/>
        <body name="link_2" pos="0.8838796815488454 -0.02 0.017780032004302074">
          <joint name="joint_2" pos="0 0 0" axis="0 1 0" range="-1.50796 1.50796" stiffness="2.0" damping="0.1"/>
          <geom name="handle" type="mesh" mesh="9962026" material="handle_material"/>
        </body>
      </body>
    </body>
  </worldbody>
</mujoco>