<mujoco model="fridge">
  <compiler angle="radian" meshdir="texture_stl/"/>

  <visual>
    <headlight diffuse="0.6 0.6 0.6" ambient="0.3 0.3 0.3" specular="0 0 0"/>
    <rgba haze="0.15 0.25 0.35 1"/>
    <global azimuth="-20" elevation="-20" ellipsoidinertia="true"/>
  </visual>

  <asset>
    <texture type="skybox" builtin="gradient" rgb1="0.3 0.5 0.7" rgb2="0 0 0" width="512" height="3072"/>
    <texture type="2d" name="groundplane" builtin="checker" mark="edge" rgb1="0.2 0.3 0.4" rgb2="0.1 0.2 0.3"
      markrgb="0.8 0.8 0.8" width="300" height="300"/>
    <texture name="fridge_texture" type="cube" file="texture_stl/texture_0.png"/>
    <texture name="handle_texture" type="2d" file="texture_stl/texture_0.png"/>
    <material name="fridge_material" texture="fridge_texture"/>
    <material name="handle_material" texture="handle_texture"/>
    <material name="groundplane" texture="groundplane" texuniform="true" texrepeat="5 5" reflectance="0.2"/>

    <mesh name="frame" file="frame.stl" scale="0.7 0.7 0.7"/>
    <mesh name="board" file="board.stl" scale="0.7 0.7 0.7"/>
    <mesh name="9960005" file="9960005.stl" scale="1.4 1.4 1.4"/>
  </asset>

  <worldbody>
    <light pos="0 0 1.5" dir="0 0 -1" directional="true"/>
    <geom name="floor" size="0 0 0.05" type="plane" material="groundplane"/>
    <body name="fridge" euler="0 1.57 0" pos="0 0 0.75">
<!--      <joint type="free"/>-->
      <geom name="frame" pos="0 0 0" quat="0.5 0.5 -0.5 -0.5" type="mesh" mesh="frame" material="fridge_material" conaffinity="0" contype="0"/>
      <body name="link_1" pos="0 0.430672 0" quat="0.5 0.5 -0.5 -0.5">
        <inertial pos="0 0 0" mass="10.0" diaginertia="5.0 5.0 5.0"/>
        <joint name="joint_1" pos="0 0 0" axis="0 0 -1" range="0 1.50796"/>
        <geom name="board" pos="0.430672 0 0" quat="1 0 0 0" type="mesh" mesh="board" material="fridge_material"/>
        <body name="link_2" pos="0.430672 -0.038  0.0470197">
          <joint name="joint_2" pos="0 0 0" axis="0 1 0" range="-1.50796 1.50796" stiffness="0.8" damping="0.01"/>
          <geom name="handle" type="mesh" mesh="9960005" material="handle_material"/>
        </body>
      </body>
    </body>
  </worldbody>
</mujoco>